data/sample_events.csv
timestamp,event_type,order_id,side,price,quantity
0,ADD_ORDER,1,SELL,99.98,5
0,MARKET_ORDER,2,BUY,,3
0,ADD_ORDER,3,SELL,99.97,2
0,ADD_ORDER,4,BUY,99.99,1
0,CANCEL_ORDER,4,,,
0,ADD_ORDER,5,BUY,100.00,3
0,CANCEL_ORDER,5,,,
0,MARKET_ORDER,6,SELL,,1
1,ADD_ORDER,7,SELL,100.03,2
1,ADD_ORDER,8,BUY,100.02,4
1,ADD_ORDER,9,SELL,99.97,2
1,CANCEL_ORDER,3,,,
1,ADD_ORDER,10,SELL,99.97,2
1,CANCEL_ORDER,10,,,
1,ADD_ORDER,11,BUY,100.00,2
1,ADD_ORDER,12,SELL,100.00,1
2,ADD_ORDER,13,SELL,99.98,5
2,MARKET_ORDER,14,SELL,,2
2,ADD_ORDER,15,SELL,99.99,5
2,ADD_ORDER,16,BUY,99.99,3
2,ADD_ORDER,17,BUY,100.01,2
2,ADD_ORDER,18,SELL,99.99,5
3,ADD_ORDER,19,SELL,100.02,3
3,ADD_ORDER,20,SELL,100.01,4
3,ADD_ORDER,21,BUY,100.05,1
3,ADD_ORDER,22,BUY,100.07,5
3,ADD_ORDER,23,BUY,100.01,3
3,ADD_ORDER,24,SELL,100.06,1
4,ADD_ORDER,25,BUY,99.95,1
4,ADD_ORDER,26,SELL,99.96,2
4,CANCEL_ORDER,24,,,
4,ADD_ORDER,27,SELL,99.97,5
4,ADD_ORDER,28,SELL,99.95,1
4,MARKET_ORDER,29,BUY,,4
4,ADD_ORDER,30,BUY,99.98,4
5,MARKET_ORDER,31,SELL,,1
5,ADD_ORDER,32,SELL,99.99,3
5,MARKET_ORDER,33,BUY,,1
5,ADD_ORDER,34,SELL,99.97,3
5,ADD_ORDER,35,SELL,100.04,1
5,ADD_ORDER,36,SELL,99.99,3
6,MARKET_ORDER,37,BUY,,1
6,ADD_ORDER,38,BUY,100.00,3
6,ADD_ORDER,39,SELL,100.01,5
6,ADD_ORDER,40,SELL,100.00,4
6,ADD_ORDER,41,BUY,100.08,3
6,ADD_ORDER,42,SELL,99.99,5
7,ADD_ORDER,43,BUY,100.01,5
7,ADD_ORDER,44,BUY,100.04,1
7,ADD_ORDER,45,SELL,100.07,3
7,ADD_ORDER,46,BUY,100.02,2
7,ADD_ORDER,47,SELL,100.04,2
7,ADD_ORDER,48,BUY,100.01,1
8,ADD_ORDER,49,BUY,100.00,2
8,ADD_ORDER,50,BUY,99.98,2
8,ADD_ORDER,51,SELL,99.98,4
8,ADD_ORDER,52,BUY,99.97,3
8,ADD_ORDER,53,SELL,99.98,3
8,ADD_ORDER,54,BUY,100.01,2
9,ADD_ORDER,55,BUY,100.05,2
9,ADD_ORDER,56,BUY,100.01,5
9,ADD_ORDER,57,BUY,100.10,3
9,CANCEL_ORDER,42,,,
9,ADD_ORDER,58,SELL,100.08,4
9,ADD_ORDER,59,BUY,100.04,1
9,ADD_ORDER,60,SELL,100.09,2
10,MARKET_ORDER,61,BUY,,2
10,ADD_ORDER,62,SELL,100.07,4
10,ADD_ORDER,63,SELL,100.06,4
10,MARKET_ORDER,64,BUY,,4
10,CANCEL_ORDER,48,,,
10,ADD_ORDER,65,BUY,100.06,2
10,ADD_ORDER,66,BUY,100.05,4
11,ADD_ORDER,67,SELL,100.03,5
11,ADD_ORDER,68,SELL,100.09,1
11,ADD_ORDER,69,BUY,100.07,5
11,ADD_ORDER,70,BUY,100.03,1
11,ADD_ORDER,71,BUY,100.07,4
11,ADD_ORDER,72,SELL,100.03,4
12,ADD_ORDER,73,BUY,100.03,5
12,ADD_ORDER,74,SELL,100.05,2
12,ADD_ORDER,75,SELL,100.03,1
12,ADD_ORDER,76,BUY,100.06,2
12,CANCEL_ORDER,51,,,
12,ADD_ORDER,77,BUY,100.07,5
12,MARKET_ORDER,78,BUY,,4
13,ADD_ORDER,79,SELL,100.03,3
13,ADD_ORDER,80,BUY,100.05,2
13,ADD_ORDER,81,SELL,100.05,4
13,CANCEL_ORDER,46,,,
13,MARKET_ORDER,82,BUY,,2
13,MARKET_ORDER,83,BUY,,5
13,ADD_ORDER,84,SELL,100.04,4
14,ADD_ORDER,85,SELL,100.09,3
14,MARKET_ORDER,86,BUY,,4
14,ADD_ORDER,87,BUY,100.03,4
14,ADD_ORDER,88,BUY,100.04,4
14,ADD_ORDER,89,BUY,100.02,5
14,ADD_ORDER,90,SELL,100.03,5
15,ADD_ORDER,91,BUY,100.03,1
15,ADD_ORDER,92,SELL,99.99,1
15,CANCEL_ORDER,1,,,
15,ADD_ORDER,93,BUY,100.01,4
15,ADD_ORDER,94,SELL,99.99,5
15,ADD_ORDER,95,BUY,100.03,3
15,ADD_ORDER,96,SELL,100.06,4
16,ADD_ORDER,97,SELL,100.06,4
16,ADD_ORDER,98,BUY,100.04,5
16,ADD_ORDER,99,SELL,100.04,2
16,CANCEL_ORDER,71,,,
16,ADD_ORDER,100,SELL,100.05,1
16,ADD_ORDER,101,SELL,100.06,4
16,ADD_ORDER,102,BUY,100.04,2
17,ADD_ORDER,103,BUY,100.04,1
17,CANCEL_ORDER,16,,,
17,ADD_ORDER,104,BUY,100.04,4
17,ADD_ORDER,105,SELL,100.12,5
17,ADD_ORDER,106,BUY,100.03,5
17,ADD_ORDER,107,BUY,100.08,2
17,ADD_ORDER,108,SELL,100.09,3
18,ADD_ORDER,109,SELL,100.05,2
18,ADD_ORDER,110,BUY,100.04,3
18,ADD_ORDER,111,BUY,100.06,2
18,ADD_ORDER,112,BUY,100.11,1
18,ADD_ORDER,113,BUY,100.02,1
18,ADD_ORDER,114,SELL,100.03,2
19,CANCEL_ORDER,59,,,
19,ADD_ORDER,115,BUY,100.04,4
19,MARKET_ORDER,116,SELL,,1
19,ADD_ORDER,117,BUY,100.08,4
19,CANCEL_ORDER,47,,,
19,ADD_ORDER,118,BUY,100.03,4
19,ADD_ORDER,119,SELL,100.06,1
19,ADD_ORDER,120,SELL,100.05,2
20,ADD_ORDER,121,BUY,100.00,1
20,ADD_ORDER,122,SELL,100.07,5
20,ADD_ORDER,123,SELL,100.03,2
20,CANCEL_ORDER,90,,,
20,MARKET_ORDER,124,SELL,,1
20,ADD_ORDER,125,SELL,100.01,3
20,ADD_ORDER,126,BUY,100.02,3
21,ADD_ORDER,127,SELL,100.02,4
21,ADD_ORDER,128,SELL,99.98,3
21,ADD_ORDER,129,SELL,99.98,1
21,ADD_ORDER,130,SELL,99.99,1
21,ADD_ORDER,131,SELL,99.98,3
21,ADD_ORDER,132,BUY,99.97,4
22,ADD_ORDER,133,SELL,99.98,5
22,ADD_ORDER,134,SELL,100.07,3
22,CANCEL_ORDER,130,,,
22,ADD_ORDER,135,BUY,99.97,4
22,ADD_ORDER,136,BUY,99.99,5
22,ADD_ORDER,137,SELL,100.00,3
22,ADD_ORDER,138,BUY,99.97,2
23,CANCEL_ORDER,110,,,
23,ADD_ORDER,139,SELL,100.09,4
23,ADD_ORDER,140,BUY,100.04,2
23,ADD_ORDER,141,SELL,100.00,1
23,ADD_ORDER,142,SELL,100.02,1
23,ADD_ORDER,143,BUY,100.04,1
23,CANCEL_ORDER,62,,,
23,ADD_ORDER,144,BUY,100.03,4
24,ADD_ORDER,145,SELL,100.03,3
24,ADD_ORDER,146,BUY,100.00,1
24,CANCEL_ORDER,115,,,
24,ADD_ORDER,147,SELL,100.06,1
24,ADD_ORDER,148,BUY,99.99,1
24,ADD_ORDER,149,SELL,99.99,5
24,CANCEL_ORDER,107,,,
24,ADD_ORDER,150,SELL,100.00,2
25,ADD_ORDER,151,SELL,99.93,4
25,ADD_ORDER,152,BUY,100.00,2
25,ADD_ORDER,153,SELL,99.93,1
25,ADD_ORDER,154,SELL,99.95,1
25,ADD_ORDER,155,SELL,99.93,3
25,ADD_ORDER,156,SELL,99.94,5
26,ADD_ORDER,157,SELL,99.95,5
26,ADD_ORDER,158,BUY,99.96,4
26,ADD_ORDER,159,BUY,99.96,4
26,ADD_ORDER,160,BUY,99.96,1
26,MARKET_ORDER,161,SELL,,1
26,ADD_ORDER,162,SELL,99.92,2
27,CANCEL_ORDER,28,,,
27,ADD_ORDER,163,SELL,99.94,2
27,ADD_ORDER,164,BUY,100.00,4
27,ADD_ORDER,165,BUY,99.94,3
27,ADD_ORDER,166,SELL,99.93,1
27,ADD_ORDER,167,BUY,99.98,3
27,ADD_ORDER,168,BUY,99.92,3
28,ADD_ORDER,169,BUY,99.92,1
28,ADD_ORDER,170,BUY,99.93,3
28,ADD_ORDER,171,BUY,99.93,1
28,ADD_ORDER,172,BUY,99.93,2
28,CANCEL_ORDER,137,,,
28,ADD_ORDER,173,BUY,99.94,3
28,ADD_ORDER,174,BUY,99.90,3
29,ADD_ORDER,175,SELL,99.93,1
29,ADD_ORDER,176,SELL,99.94,2
29,ADD_ORDER,177,SELL,99.94,5
29,ADD_ORDER,178,SELL,99.94,4
29,ADD_ORDER,179,SELL,99.93,3
29,ADD_ORDER,180,BUY,99.92,4
30,ADD_ORDER,181,SELL,99.92,2
30,ADD_ORDER,182,BUY,99.92,5
30,CANCEL_ORDER,70,,,
30,ADD_ORDER,183,BUY,99.94,1
30,ADD_ORDER,184,BUY,99.91,1
30,ADD_ORDER,185,BUY,99.93,3
30,ADD_ORDER,186,BUY,99.94,1
31,CANCEL_ORDER,159,,,
31,ADD_ORDER,187,SELL,99.92,4
31,CANCEL_ORDER,60,,,
31,ADD_ORDER,188,SELL,99.93,3
31,CANCEL_ORDER,104,,,
31,ADD_ORDER,189,SELL,100.00,5
31,CANCEL_ORDER,9,,,
31,MARKET_ORDER,190,SELL,,5
31,ADD_ORDER,191,SELL,99.94,3
31,ADD_ORDER,192,SELL,99.92,1
32,ADD_ORDER,193,SELL,99.94,2
32,CANCEL_ORDER,180,,,
32,ADD_ORDER,194,BUY,99.96,2
32,ADD_ORDER,195,BUY,99.92,4
32,CANCEL_ORDER,191,,,
32,MARKET_ORDER,196,BUY,,4
32,ADD_ORDER,197,SELL,99.92,2
32,ADD_ORDER,198,SELL,99.96,2
33,ADD_ORDER,199,SELL,99.93,4
33,ADD_ORDER,200,BUY,99.90,5
33,CANCEL_ORDER,73,,,
33,ADD_ORDER,201,SELL,99.97,3
33,ADD_ORDER,202,SELL,99.89,2
33,ADD_ORDER,203,BUY,99.93,5
33,CANCEL_ORDER,140,,,
33,ADD_ORDER,204,SELL,99.96,5
34,MARKET_ORDER,205,BUY,,5
34,ADD_ORDER,206,SELL,99.92,2
34,CANCEL_ORDER,184,,,
34,MARKET_ORDER,207,BUY,,2
34,ADD_ORDER,208,SELL,99.92,5
34,ADD_ORDER,209,BUY,99.93,3
34,ADD_ORDER,210,BUY,99.95,2
35,CANCEL_ORDER,65,,,
35,ADD_ORDER,211,SELL,99.94,5
35,ADD_ORDER,212,BUY,99.92,3
35,CANCEL_ORDER,36,,,
35,ADD_ORDER,213,SELL,99.95,5
35,ADD_ORDER,214,BUY,99.91,2
35,ADD_ORDER,215,SELL,99.93,4
35,MARKET_ORDER,216,BUY,,1
36,MARKET_ORDER,217,BUY,,5
36,CANCEL_ORDER,96,,,
36,ADD_ORDER,218,SELL,99.95,4
36,ADD_ORDER,219,BUY,99.91,1
36,ADD_ORDER,220,SELL,100.01,3
36,CANCEL_ORDER,101,,,
36,ADD_ORDER,221,BUY,99.95,3
36,CANCEL_ORDER,133,,,
36,ADD_ORDER,222,BUY,100.00,4
37,ADD_ORDER,223,SELL,99.93,2
37,MARKET_ORDER,224,BUY,,5
37,ADD_ORDER,225,BUY,99.92,2
37,CANCEL_ORDER,81,,,
37,ADD_ORDER,226,SELL,99.95,5
37,CANCEL_ORDER,220,,,
37,ADD_ORDER,227,BUY,99.90,4
37,ADD_ORDER,228,SELL,99.92,3
38,CANCEL_ORDER,155,,,
38,MARKET_ORDER,229,BUY,,2
38,ADD_ORDER,230,BUY,99.90,5
38,ADD_ORDER,231,SELL,99.92,5
38,CANCEL_ORDER,209,,,
38,ADD_ORDER,232,BUY,99.97,1
38,ADD_ORDER,233,BUY,99.89,1
38,ADD_ORDER,234,SELL,99.90,4
39,ADD_ORDER,235,SELL,99.92,3
39,ADD_ORDER,236,SELL,99.94,2
39,ADD_ORDER,237,SELL,99.92,4
39,ADD_ORDER,238,BUY,99.93,4
39,ADD_ORDER,239,SELL,99.93,5
39,ADD_ORDER,240,SELL,99.98,1
40,ADD_ORDER,241,SELL,100.03,1
40,MARKET_ORDER,242,BUY,,2
40,CANCEL_ORDER,142,,,
